nohup: ignoring input
[2024-04-03 08:14:08 +0000] [1358803] [INFO] Starting gunicorn 21.2.0
[2024-04-03 08:14:08 +0000] [1358803] [INFO] Listening at: http://0.0.0.0:8000 (1358803)
[2024-04-03 08:14:08 +0000] [1358803] [INFO] Using worker: uvicorn.workers.UvicornWorker
[2024-04-03 08:14:08 +0000] [1358808] [INFO] Booting worker with pid: 1358808
[2024-04-03 08:14:08 +0000] [1358809] [INFO] Booting worker with pid: 1358809
[2024-04-03 08:14:15 +0000] [1358808] [INFO] Started server process [1358808]
[2024-04-03 08:14:15 +0000] [1358808] [INFO] Waiting for application startup.
[2024-04-03 08:14:15 +0000] [1358808] [INFO] Application startup complete.
[2024-04-03 08:14:15 +0000] [1358809] [INFO] Started server process [1358809]
[2024-04-03 08:14:15 +0000] [1358809] [INFO] Waiting for application startup.
[2024-04-03 08:14:15 +0000] [1358809] [INFO] Application startup complete.
[2024-04-03 08:14:29 +0000] [1358803] [INFO] Handling signal: hup
[2024-04-03 08:14:29 +0000] [1358803] [INFO] Hang up: Master
[2024-04-03 08:14:29 +0000] [1358944] [INFO] Booting worker with pid: 1358944
[2024-04-03 08:14:29 +0000] [1358945] [INFO] Booting worker with pid: 1358945
[2024-04-03 08:14:29 +0000] [1358803] [ERROR] Worker (pid:1358808) was sent SIGHUP!
[2024-04-03 08:14:29 +0000] [1358803] [ERROR] Worker (pid:1358809) was sent SIGHUP!
[2024-04-03 08:14:36 +0000] [1358945] [INFO] Started server process [1358945]
[2024-04-03 08:14:36 +0000] [1358945] [INFO] Waiting for application startup.
[2024-04-03 08:14:36 +0000] [1358945] [INFO] Application startup complete.
[2024-04-03 08:14:36 +0000] [1358944] [INFO] Started server process [1358944]
[2024-04-03 08:14:36 +0000] [1358944] [INFO] Waiting for application startup.
[2024-04-03 08:14:36 +0000] [1358944] [INFO] Application startup complete.
[2024-04-03 08:15:31 +0000] [1358945] [ERROR] Exception in ASGI application
Traceback (most recent call last):
  File "/home/ttytu/anaconda3/envs/korcat/lib/python3.9/site-packages/uvicorn/protocols/http/h11_impl.py", line 404, in run_asgi
    result = await app(  # type: ignore[func-returns-value]
  File "/home/ttytu/anaconda3/envs/korcat/lib/python3.9/site-packages/uvicorn/middleware/proxy_headers.py", line 84, in __call__
    return await self.app(scope, receive, send)
  File "/home/ttytu/anaconda3/envs/korcat/lib/python3.9/site-packages/fastapi/applications.py", line 1054, in __call__
    await super().__call__(scope, receive, send)
  File "/home/ttytu/anaconda3/envs/korcat/lib/python3.9/site-packages/starlette/applications.py", line 123, in __call__
    await self.middleware_stack(scope, receive, send)
  File "/home/ttytu/anaconda3/envs/korcat/lib/python3.9/site-packages/starlette/middleware/errors.py", line 186, in __call__
    raise exc
  File "/home/ttytu/anaconda3/envs/korcat/lib/python3.9/site-packages/starlette/middleware/errors.py", line 164, in __call__
    await self.app(scope, receive, _send)
  File "/home/ttytu/anaconda3/envs/korcat/lib/python3.9/site-packages/starlette/middleware/cors.py", line 91, in __call__
    await self.simple_response(scope, receive, send, request_headers=headers)
  File "/home/ttytu/anaconda3/envs/korcat/lib/python3.9/site-packages/starlette/middleware/cors.py", line 146, in simple_response
    await self.app(scope, receive, send)
  File "/home/ttytu/anaconda3/envs/korcat/lib/python3.9/site-packages/starlette/middleware/exceptions.py", line 62, in __call__
    await wrap_app_handling_exceptions(self.app, conn)(scope, receive, send)
  File "/home/ttytu/anaconda3/envs/korcat/lib/python3.9/site-packages/starlette/_exception_handler.py", line 64, in wrapped_app
    raise exc
  File "/home/ttytu/anaconda3/envs/korcat/lib/python3.9/site-packages/starlette/_exception_handler.py", line 53, in wrapped_app
    await app(scope, receive, sender)
  File "/home/ttytu/anaconda3/envs/korcat/lib/python3.9/site-packages/starlette/routing.py", line 762, in __call__
    await self.middleware_stack(scope, receive, send)
  File "/home/ttytu/anaconda3/envs/korcat/lib/python3.9/site-packages/starlette/routing.py", line 782, in app
    await route.handle(scope, receive, send)
  File "/home/ttytu/anaconda3/envs/korcat/lib/python3.9/site-packages/starlette/routing.py", line 297, in handle
    await self.app(scope, receive, send)
  File "/home/ttytu/anaconda3/envs/korcat/lib/python3.9/site-packages/starlette/routing.py", line 77, in app
    await wrap_app_handling_exceptions(app, request)(scope, receive, send)
  File "/home/ttytu/anaconda3/envs/korcat/lib/python3.9/site-packages/starlette/_exception_handler.py", line 64, in wrapped_app
    raise exc
  File "/home/ttytu/anaconda3/envs/korcat/lib/python3.9/site-packages/starlette/_exception_handler.py", line 53, in wrapped_app
    await app(scope, receive, sender)
  File "/home/ttytu/anaconda3/envs/korcat/lib/python3.9/site-packages/starlette/routing.py", line 75, in app
    await response(scope, receive, send)
  File "/home/ttytu/anaconda3/envs/korcat/lib/python3.9/site-packages/starlette/responses.py", line 155, in __call__
    await send({"type": "http.response.body", "body": self.body})
  File "/home/ttytu/anaconda3/envs/korcat/lib/python3.9/site-packages/starlette/_exception_handler.py", line 50, in sender
    await send(message)
  File "/home/ttytu/anaconda3/envs/korcat/lib/python3.9/site-packages/starlette/_exception_handler.py", line 50, in sender
    await send(message)
  File "/home/ttytu/anaconda3/envs/korcat/lib/python3.9/site-packages/starlette/middleware/cors.py", line 152, in send
    await send(message)
  File "/home/ttytu/anaconda3/envs/korcat/lib/python3.9/site-packages/starlette/middleware/errors.py", line 161, in _send
    await send(message)
  File "/home/ttytu/anaconda3/envs/korcat/lib/python3.9/site-packages/uvicorn/protocols/http/h11_impl.py", line 501, in send
    output = self.conn.send(event=h11.Data(data=data))
  File "/home/ttytu/anaconda3/envs/korcat/lib/python3.9/site-packages/h11/_connection.py", line 512, in send
    data_list = self.send_with_data_passthrough(event)
  File "/home/ttytu/anaconda3/envs/korcat/lib/python3.9/site-packages/h11/_connection.py", line 545, in send_with_data_passthrough
    writer(event, data_list.append)
  File "/home/ttytu/anaconda3/envs/korcat/lib/python3.9/site-packages/h11/_writers.py", line 65, in __call__
    self.send_data(event.data, write)
  File "/home/ttytu/anaconda3/envs/korcat/lib/python3.9/site-packages/h11/_writers.py", line 91, in send_data
    raise LocalProtocolError("Too much data for declared Content-Length")
h11._util.LocalProtocolError: Too much data for declared Content-Length
[2024-04-03 08:15:33 +0000] [1358944] [ERROR] Exception in ASGI application
Traceback (most recent call last):
  File "/home/ttytu/anaconda3/envs/korcat/lib/python3.9/site-packages/uvicorn/protocols/http/h11_impl.py", line 404, in run_asgi
    result = await app(  # type: ignore[func-returns-value]
  File "/home/ttytu/anaconda3/envs/korcat/lib/python3.9/site-packages/uvicorn/middleware/proxy_headers.py", line 84, in __call__
    return await self.app(scope, receive, send)
  File "/home/ttytu/anaconda3/envs/korcat/lib/python3.9/site-packages/fastapi/applications.py", line 1054, in __call__
    await super().__call__(scope, receive, send)
  File "/home/ttytu/anaconda3/envs/korcat/lib/python3.9/site-packages/starlette/applications.py", line 123, in __call__
    await self.middleware_stack(scope, receive, send)
  File "/home/ttytu/anaconda3/envs/korcat/lib/python3.9/site-packages/starlette/middleware/errors.py", line 186, in __call__
    raise exc
  File "/home/ttytu/anaconda3/envs/korcat/lib/python3.9/site-packages/starlette/middleware/errors.py", line 164, in __call__
    await self.app(scope, receive, _send)
  File "/home/ttytu/anaconda3/envs/korcat/lib/python3.9/site-packages/starlette/middleware/cors.py", line 91, in __call__
    await self.simple_response(scope, receive, send, request_headers=headers)
  File "/home/ttytu/anaconda3/envs/korcat/lib/python3.9/site-packages/starlette/middleware/cors.py", line 146, in simple_response
    await self.app(scope, receive, send)
  File "/home/ttytu/anaconda3/envs/korcat/lib/python3.9/site-packages/starlette/middleware/exceptions.py", line 62, in __call__
    await wrap_app_handling_exceptions(self.app, conn)(scope, receive, send)
  File "/home/ttytu/anaconda3/envs/korcat/lib/python3.9/site-packages/starlette/_exception_handler.py", line 64, in wrapped_app
    raise exc
  File "/home/ttytu/anaconda3/envs/korcat/lib/python3.9/site-packages/starlette/_exception_handler.py", line 53, in wrapped_app
    await app(scope, receive, sender)
  File "/home/ttytu/anaconda3/envs/korcat/lib/python3.9/site-packages/starlette/routing.py", line 762, in __call__
    await self.middleware_stack(scope, receive, send)
  File "/home/ttytu/anaconda3/envs/korcat/lib/python3.9/site-packages/starlette/routing.py", line 782, in app
    await route.handle(scope, receive, send)
  File "/home/ttytu/anaconda3/envs/korcat/lib/python3.9/site-packages/starlette/routing.py", line 297, in handle
    await self.app(scope, receive, send)
  File "/home/ttytu/anaconda3/envs/korcat/lib/python3.9/site-packages/starlette/routing.py", line 77, in app
    await wrap_app_handling_exceptions(app, request)(scope, receive, send)
  File "/home/ttytu/anaconda3/envs/korcat/lib/python3.9/site-packages/starlette/_exception_handler.py", line 64, in wrapped_app
    raise exc
  File "/home/ttytu/anaconda3/envs/korcat/lib/python3.9/site-packages/starlette/_exception_handler.py", line 53, in wrapped_app
    await app(scope, receive, sender)
  File "/home/ttytu/anaconda3/envs/korcat/lib/python3.9/site-packages/starlette/routing.py", line 75, in app
    await response(scope, receive, send)
  File "/home/ttytu/anaconda3/envs/korcat/lib/python3.9/site-packages/starlette/responses.py", line 155, in __call__
    await send({"type": "http.response.body", "body": self.body})
  File "/home/ttytu/anaconda3/envs/korcat/lib/python3.9/site-packages/starlette/_exception_handler.py", line 50, in sender
    await send(message)
  File "/home/ttytu/anaconda3/envs/korcat/lib/python3.9/site-packages/starlette/_exception_handler.py", line 50, in sender
    await send(message)
  File "/home/ttytu/anaconda3/envs/korcat/lib/python3.9/site-packages/starlette/middleware/cors.py", line 152, in send
    await send(message)
  File "/home/ttytu/anaconda3/envs/korcat/lib/python3.9/site-packages/starlette/middleware/errors.py", line 161, in _send
    await send(message)
  File "/home/ttytu/anaconda3/envs/korcat/lib/python3.9/site-packages/uvicorn/protocols/http/h11_impl.py", line 501, in send
    output = self.conn.send(event=h11.Data(data=data))
  File "/home/ttytu/anaconda3/envs/korcat/lib/python3.9/site-packages/h11/_connection.py", line 512, in send
    data_list = self.send_with_data_passthrough(event)
  File "/home/ttytu/anaconda3/envs/korcat/lib/python3.9/site-packages/h11/_connection.py", line 545, in send_with_data_passthrough
    writer(event, data_list.append)
  File "/home/ttytu/anaconda3/envs/korcat/lib/python3.9/site-packages/h11/_writers.py", line 65, in __call__
    self.send_data(event.data, write)
  File "/home/ttytu/anaconda3/envs/korcat/lib/python3.9/site-packages/h11/_writers.py", line 91, in send_data
    raise LocalProtocolError("Too much data for declared Content-Length")
h11._util.LocalProtocolError: Too much data for declared Content-Length
[2024-04-03 08:15:36 +0000] [1358944] [ERROR] Exception in ASGI application
Traceback (most recent call last):
  File "/home/ttytu/anaconda3/envs/korcat/lib/python3.9/site-packages/uvicorn/protocols/http/h11_impl.py", line 404, in run_asgi
    result = await app(  # type: ignore[func-returns-value]
  File "/home/ttytu/anaconda3/envs/korcat/lib/python3.9/site-packages/uvicorn/middleware/proxy_headers.py", line 84, in __call__
    return await self.app(scope, receive, send)
  File "/home/ttytu/anaconda3/envs/korcat/lib/python3.9/site-packages/fastapi/applications.py", line 1054, in __call__
    await super().__call__(scope, receive, send)
  File "/home/ttytu/anaconda3/envs/korcat/lib/python3.9/site-packages/starlette/applications.py", line 123, in __call__
    await self.middleware_stack(scope, receive, send)
  File "/home/ttytu/anaconda3/envs/korcat/lib/python3.9/site-packages/starlette/middleware/errors.py", line 186, in __call__
    raise exc
  File "/home/ttytu/anaconda3/envs/korcat/lib/python3.9/site-packages/starlette/middleware/errors.py", line 164, in __call__
    await self.app(scope, receive, _send)
  File "/home/ttytu/anaconda3/envs/korcat/lib/python3.9/site-packages/starlette/middleware/cors.py", line 91, in __call__
    await self.simple_response(scope, receive, send, request_headers=headers)
  File "/home/ttytu/anaconda3/envs/korcat/lib/python3.9/site-packages/starlette/middleware/cors.py", line 146, in simple_response
    await self.app(scope, receive, send)
  File "/home/ttytu/anaconda3/envs/korcat/lib/python3.9/site-packages/starlette/middleware/exceptions.py", line 62, in __call__
    await wrap_app_handling_exceptions(self.app, conn)(scope, receive, send)
  File "/home/ttytu/anaconda3/envs/korcat/lib/python3.9/site-packages/starlette/_exception_handler.py", line 64, in wrapped_app
    raise exc
  File "/home/ttytu/anaconda3/envs/korcat/lib/python3.9/site-packages/starlette/_exception_handler.py", line 53, in wrapped_app
    await app(scope, receive, sender)
  File "/home/ttytu/anaconda3/envs/korcat/lib/python3.9/site-packages/starlette/routing.py", line 762, in __call__
    await self.middleware_stack(scope, receive, send)
  File "/home/ttytu/anaconda3/envs/korcat/lib/python3.9/site-packages/starlette/routing.py", line 782, in app
    await route.handle(scope, receive, send)
  File "/home/ttytu/anaconda3/envs/korcat/lib/python3.9/site-packages/starlette/routing.py", line 297, in handle
    await self.app(scope, receive, send)
  File "/home/ttytu/anaconda3/envs/korcat/lib/python3.9/site-packages/starlette/routing.py", line 77, in app
    await wrap_app_handling_exceptions(app, request)(scope, receive, send)
  File "/home/ttytu/anaconda3/envs/korcat/lib/python3.9/site-packages/starlette/_exception_handler.py", line 64, in wrapped_app
    raise exc
  File "/home/ttytu/anaconda3/envs/korcat/lib/python3.9/site-packages/starlette/_exception_handler.py", line 53, in wrapped_app
    await app(scope, receive, sender)
  File "/home/ttytu/anaconda3/envs/korcat/lib/python3.9/site-packages/starlette/routing.py", line 75, in app
    await response(scope, receive, send)
  File "/home/ttytu/anaconda3/envs/korcat/lib/python3.9/site-packages/starlette/responses.py", line 155, in __call__
    await send({"type": "http.response.body", "body": self.body})
  File "/home/ttytu/anaconda3/envs/korcat/lib/python3.9/site-packages/starlette/_exception_handler.py", line 50, in sender
    await send(message)
  File "/home/ttytu/anaconda3/envs/korcat/lib/python3.9/site-packages/starlette/_exception_handler.py", line 50, in sender
    await send(message)
  File "/home/ttytu/anaconda3/envs/korcat/lib/python3.9/site-packages/starlette/middleware/cors.py", line 152, in send
    await send(message)
  File "/home/ttytu/anaconda3/envs/korcat/lib/python3.9/site-packages/starlette/middleware/errors.py", line 161, in _send
    await send(message)
  File "/home/ttytu/anaconda3/envs/korcat/lib/python3.9/site-packages/uvicorn/protocols/http/h11_impl.py", line 501, in send
    output = self.conn.send(event=h11.Data(data=data))
  File "/home/ttytu/anaconda3/envs/korcat/lib/python3.9/site-packages/h11/_connection.py", line 512, in send
    data_list = self.send_with_data_passthrough(event)
  File "/home/ttytu/anaconda3/envs/korcat/lib/python3.9/site-packages/h11/_connection.py", line 545, in send_with_data_passthrough
    writer(event, data_list.append)
  File "/home/ttytu/anaconda3/envs/korcat/lib/python3.9/site-packages/h11/_writers.py", line 65, in __call__
    self.send_data(event.data, write)
  File "/home/ttytu/anaconda3/envs/korcat/lib/python3.9/site-packages/h11/_writers.py", line 91, in send_data
    raise LocalProtocolError("Too much data for declared Content-Length")
h11._util.LocalProtocolError: Too much data for declared Content-Length
[2024-04-03 08:15:37 +0000] [1358944] [ERROR] Exception in ASGI application
Traceback (most recent call last):
  File "/home/ttytu/anaconda3/envs/korcat/lib/python3.9/site-packages/uvicorn/protocols/http/h11_impl.py", line 404, in run_asgi
    result = await app(  # type: ignore[func-returns-value]
  File "/home/ttytu/anaconda3/envs/korcat/lib/python3.9/site-packages/uvicorn/middleware/proxy_headers.py", line 84, in __call__
    return await self.app(scope, receive, send)
  File "/home/ttytu/anaconda3/envs/korcat/lib/python3.9/site-packages/fastapi/applications.py", line 1054, in __call__
    await super().__call__(scope, receive, send)
  File "/home/ttytu/anaconda3/envs/korcat/lib/python3.9/site-packages/starlette/applications.py", line 123, in __call__
    await self.middleware_stack(scope, receive, send)
  File "/home/ttytu/anaconda3/envs/korcat/lib/python3.9/site-packages/starlette/middleware/errors.py", line 186, in __call__
    raise exc
  File "/home/ttytu/anaconda3/envs/korcat/lib/python3.9/site-packages/starlette/middleware/errors.py", line 164, in __call__
    await self.app(scope, receive, _send)
  File "/home/ttytu/anaconda3/envs/korcat/lib/python3.9/site-packages/starlette/middleware/cors.py", line 91, in __call__
    await self.simple_response(scope, receive, send, request_headers=headers)
  File "/home/ttytu/anaconda3/envs/korcat/lib/python3.9/site-packages/starlette/middleware/cors.py", line 146, in simple_response
    await self.app(scope, receive, send)
  File "/home/ttytu/anaconda3/envs/korcat/lib/python3.9/site-packages/starlette/middleware/exceptions.py", line 62, in __call__
    await wrap_app_handling_exceptions(self.app, conn)(scope, receive, send)
  File "/home/ttytu/anaconda3/envs/korcat/lib/python3.9/site-packages/starlette/_exception_handler.py", line 64, in wrapped_app
    raise exc
  File "/home/ttytu/anaconda3/envs/korcat/lib/python3.9/site-packages/starlette/_exception_handler.py", line 53, in wrapped_app
    await app(scope, receive, sender)
  File "/home/ttytu/anaconda3/envs/korcat/lib/python3.9/site-packages/starlette/routing.py", line 762, in __call__
    await self.middleware_stack(scope, receive, send)
  File "/home/ttytu/anaconda3/envs/korcat/lib/python3.9/site-packages/starlette/routing.py", line 782, in app
    await route.handle(scope, receive, send)
  File "/home/ttytu/anaconda3/envs/korcat/lib/python3.9/site-packages/starlette/routing.py", line 297, in handle
    await self.app(scope, receive, send)
  File "/home/ttytu/anaconda3/envs/korcat/lib/python3.9/site-packages/starlette/routing.py", line 77, in app
    await wrap_app_handling_exceptions(app, request)(scope, receive, send)
  File "/home/ttytu/anaconda3/envs/korcat/lib/python3.9/site-packages/starlette/_exception_handler.py", line 64, in wrapped_app
    raise exc
  File "/home/ttytu/anaconda3/envs/korcat/lib/python3.9/site-packages/starlette/_exception_handler.py", line 53, in wrapped_app
    await app(scope, receive, sender)
  File "/home/ttytu/anaconda3/envs/korcat/lib/python3.9/site-packages/starlette/routing.py", line 75, in app
    await response(scope, receive, send)
  File "/home/ttytu/anaconda3/envs/korcat/lib/python3.9/site-packages/starlette/responses.py", line 155, in __call__
    await send({"type": "http.response.body", "body": self.body})
  File "/home/ttytu/anaconda3/envs/korcat/lib/python3.9/site-packages/starlette/_exception_handler.py", line 50, in sender
    await send(message)
  File "/home/ttytu/anaconda3/envs/korcat/lib/python3.9/site-packages/starlette/_exception_handler.py", line 50, in sender
    await send(message)
  File "/home/ttytu/anaconda3/envs/korcat/lib/python3.9/site-packages/starlette/middleware/cors.py", line 152, in send
    await send(message)
  File "/home/ttytu/anaconda3/envs/korcat/lib/python3.9/site-packages/starlette/middleware/errors.py", line 161, in _send
    await send(message)
  File "/home/ttytu/anaconda3/envs/korcat/lib/python3.9/site-packages/uvicorn/protocols/http/h11_impl.py", line 501, in send
    output = self.conn.send(event=h11.Data(data=data))
  File "/home/ttytu/anaconda3/envs/korcat/lib/python3.9/site-packages/h11/_connection.py", line 512, in send
    data_list = self.send_with_data_passthrough(event)
  File "/home/ttytu/anaconda3/envs/korcat/lib/python3.9/site-packages/h11/_connection.py", line 545, in send_with_data_passthrough
    writer(event, data_list.append)
  File "/home/ttytu/anaconda3/envs/korcat/lib/python3.9/site-packages/h11/_writers.py", line 65, in __call__
    self.send_data(event.data, write)
  File "/home/ttytu/anaconda3/envs/korcat/lib/python3.9/site-packages/h11/_writers.py", line 91, in send_data
    raise LocalProtocolError("Too much data for declared Content-Length")
h11._util.LocalProtocolError: Too much data for declared Content-Length
[2024-04-03 08:15:38 +0000] [1358945] [ERROR] Exception in ASGI application
Traceback (most recent call last):
  File "/home/ttytu/anaconda3/envs/korcat/lib/python3.9/site-packages/uvicorn/protocols/http/h11_impl.py", line 404, in run_asgi
    result = await app(  # type: ignore[func-returns-value]
  File "/home/ttytu/anaconda3/envs/korcat/lib/python3.9/site-packages/uvicorn/middleware/proxy_headers.py", line 84, in __call__
    return await self.app(scope, receive, send)
  File "/home/ttytu/anaconda3/envs/korcat/lib/python3.9/site-packages/fastapi/applications.py", line 1054, in __call__
    await super().__call__(scope, receive, send)
  File "/home/ttytu/anaconda3/envs/korcat/lib/python3.9/site-packages/starlette/applications.py", line 123, in __call__
    await self.middleware_stack(scope, receive, send)
  File "/home/ttytu/anaconda3/envs/korcat/lib/python3.9/site-packages/starlette/middleware/errors.py", line 186, in __call__
    raise exc
  File "/home/ttytu/anaconda3/envs/korcat/lib/python3.9/site-packages/starlette/middleware/errors.py", line 164, in __call__
    await self.app(scope, receive, _send)
  File "/home/ttytu/anaconda3/envs/korcat/lib/python3.9/site-packages/starlette/middleware/cors.py", line 91, in __call__
    await self.simple_response(scope, receive, send, request_headers=headers)
  File "/home/ttytu/anaconda3/envs/korcat/lib/python3.9/site-packages/starlette/middleware/cors.py", line 146, in simple_response
    await self.app(scope, receive, send)
  File "/home/ttytu/anaconda3/envs/korcat/lib/python3.9/site-packages/starlette/middleware/exceptions.py", line 62, in __call__
    await wrap_app_handling_exceptions(self.app, conn)(scope, receive, send)
  File "/home/ttytu/anaconda3/envs/korcat/lib/python3.9/site-packages/starlette/_exception_handler.py", line 64, in wrapped_app
    raise exc
  File "/home/ttytu/anaconda3/envs/korcat/lib/python3.9/site-packages/starlette/_exception_handler.py", line 53, in wrapped_app
    await app(scope, receive, sender)
  File "/home/ttytu/anaconda3/envs/korcat/lib/python3.9/site-packages/starlette/routing.py", line 762, in __call__
    await self.middleware_stack(scope, receive, send)
  File "/home/ttytu/anaconda3/envs/korcat/lib/python3.9/site-packages/starlette/routing.py", line 782, in app
    await route.handle(scope, receive, send)
  File "/home/ttytu/anaconda3/envs/korcat/lib/python3.9/site-packages/starlette/routing.py", line 297, in handle
    await self.app(scope, receive, send)
  File "/home/ttytu/anaconda3/envs/korcat/lib/python3.9/site-packages/starlette/routing.py", line 77, in app
    await wrap_app_handling_exceptions(app, request)(scope, receive, send)
  File "/home/ttytu/anaconda3/envs/korcat/lib/python3.9/site-packages/starlette/_exception_handler.py", line 64, in wrapped_app
    raise exc
  File "/home/ttytu/anaconda3/envs/korcat/lib/python3.9/site-packages/starlette/_exception_handler.py", line 53, in wrapped_app
    await app(scope, receive, sender)
  File "/home/ttytu/anaconda3/envs/korcat/lib/python3.9/site-packages/starlette/routing.py", line 75, in app
    await response(scope, receive, send)
  File "/home/ttytu/anaconda3/envs/korcat/lib/python3.9/site-packages/starlette/responses.py", line 155, in __call__
    await send({"type": "http.response.body", "body": self.body})
  File "/home/ttytu/anaconda3/envs/korcat/lib/python3.9/site-packages/starlette/_exception_handler.py", line 50, in sender
    await send(message)
  File "/home/ttytu/anaconda3/envs/korcat/lib/python3.9/site-packages/starlette/_exception_handler.py", line 50, in sender
    await send(message)
  File "/home/ttytu/anaconda3/envs/korcat/lib/python3.9/site-packages/starlette/middleware/cors.py", line 152, in send
    await send(message)
  File "/home/ttytu/anaconda3/envs/korcat/lib/python3.9/site-packages/starlette/middleware/errors.py", line 161, in _send
    await send(message)
  File "/home/ttytu/anaconda3/envs/korcat/lib/python3.9/site-packages/uvicorn/protocols/http/h11_impl.py", line 501, in send
    output = self.conn.send(event=h11.Data(data=data))
  File "/home/ttytu/anaconda3/envs/korcat/lib/python3.9/site-packages/h11/_connection.py", line 512, in send
    data_list = self.send_with_data_passthrough(event)
  File "/home/ttytu/anaconda3/envs/korcat/lib/python3.9/site-packages/h11/_connection.py", line 545, in send_with_data_passthrough
    writer(event, data_list.append)
  File "/home/ttytu/anaconda3/envs/korcat/lib/python3.9/site-packages/h11/_writers.py", line 65, in __call__
    self.send_data(event.data, write)
  File "/home/ttytu/anaconda3/envs/korcat/lib/python3.9/site-packages/h11/_writers.py", line 91, in send_data
    raise LocalProtocolError("Too much data for declared Content-Length")
h11._util.LocalProtocolError: Too much data for declared Content-Length
[2024-04-03 11:23:12 +0000] [1358945] [ERROR] Exception in ASGI application
Traceback (most recent call last):
  File "/home/ttytu/anaconda3/envs/korcat/lib/python3.9/site-packages/uvicorn/protocols/http/h11_impl.py", line 404, in run_asgi
    result = await app(  # type: ignore[func-returns-value]
  File "/home/ttytu/anaconda3/envs/korcat/lib/python3.9/site-packages/uvicorn/middleware/proxy_headers.py", line 84, in __call__
    return await self.app(scope, receive, send)
  File "/home/ttytu/anaconda3/envs/korcat/lib/python3.9/site-packages/fastapi/applications.py", line 1054, in __call__
    await super().__call__(scope, receive, send)
  File "/home/ttytu/anaconda3/envs/korcat/lib/python3.9/site-packages/starlette/applications.py", line 123, in __call__
    await self.middleware_stack(scope, receive, send)
  File "/home/ttytu/anaconda3/envs/korcat/lib/python3.9/site-packages/starlette/middleware/errors.py", line 186, in __call__
    raise exc
  File "/home/ttytu/anaconda3/envs/korcat/lib/python3.9/site-packages/starlette/middleware/errors.py", line 164, in __call__
    await self.app(scope, receive, _send)
  File "/home/ttytu/anaconda3/envs/korcat/lib/python3.9/site-packages/starlette/middleware/cors.py", line 91, in __call__
    await self.simple_response(scope, receive, send, request_headers=headers)
  File "/home/ttytu/anaconda3/envs/korcat/lib/python3.9/site-packages/starlette/middleware/cors.py", line 146, in simple_response
    await self.app(scope, receive, send)
  File "/home/ttytu/anaconda3/envs/korcat/lib/python3.9/site-packages/starlette/middleware/exceptions.py", line 62, in __call__
    await wrap_app_handling_exceptions(self.app, conn)(scope, receive, send)
  File "/home/ttytu/anaconda3/envs/korcat/lib/python3.9/site-packages/starlette/_exception_handler.py", line 64, in wrapped_app
    raise exc
  File "/home/ttytu/anaconda3/envs/korcat/lib/python3.9/site-packages/starlette/_exception_handler.py", line 53, in wrapped_app
    await app(scope, receive, sender)
  File "/home/ttytu/anaconda3/envs/korcat/lib/python3.9/site-packages/starlette/routing.py", line 762, in __call__
    await self.middleware_stack(scope, receive, send)
  File "/home/ttytu/anaconda3/envs/korcat/lib/python3.9/site-packages/starlette/routing.py", line 782, in app
    await route.handle(scope, receive, send)
  File "/home/ttytu/anaconda3/envs/korcat/lib/python3.9/site-packages/starlette/routing.py", line 297, in handle
    await self.app(scope, receive, send)
  File "/home/ttytu/anaconda3/envs/korcat/lib/python3.9/site-packages/starlette/routing.py", line 77, in app
    await wrap_app_handling_exceptions(app, request)(scope, receive, send)
  File "/home/ttytu/anaconda3/envs/korcat/lib/python3.9/site-packages/starlette/_exception_handler.py", line 64, in wrapped_app
    raise exc
  File "/home/ttytu/anaconda3/envs/korcat/lib/python3.9/site-packages/starlette/_exception_handler.py", line 53, in wrapped_app
    await app(scope, receive, sender)
  File "/home/ttytu/anaconda3/envs/korcat/lib/python3.9/site-packages/starlette/routing.py", line 75, in app
    await response(scope, receive, send)
  File "/home/ttytu/anaconda3/envs/korcat/lib/python3.9/site-packages/starlette/responses.py", line 155, in __call__
    await send({"type": "http.response.body", "body": self.body})
  File "/home/ttytu/anaconda3/envs/korcat/lib/python3.9/site-packages/starlette/_exception_handler.py", line 50, in sender
    await send(message)
  File "/home/ttytu/anaconda3/envs/korcat/lib/python3.9/site-packages/starlette/_exception_handler.py", line 50, in sender
    await send(message)
  File "/home/ttytu/anaconda3/envs/korcat/lib/python3.9/site-packages/starlette/middleware/cors.py", line 152, in send
    await send(message)
  File "/home/ttytu/anaconda3/envs/korcat/lib/python3.9/site-packages/starlette/middleware/errors.py", line 161, in _send
    await send(message)
  File "/home/ttytu/anaconda3/envs/korcat/lib/python3.9/site-packages/uvicorn/protocols/http/h11_impl.py", line 501, in send
    output = self.conn.send(event=h11.Data(data=data))
  File "/home/ttytu/anaconda3/envs/korcat/lib/python3.9/site-packages/h11/_connection.py", line 512, in send
    data_list = self.send_with_data_passthrough(event)
  File "/home/ttytu/anaconda3/envs/korcat/lib/python3.9/site-packages/h11/_connection.py", line 545, in send_with_data_passthrough
    writer(event, data_list.append)
  File "/home/ttytu/anaconda3/envs/korcat/lib/python3.9/site-packages/h11/_writers.py", line 65, in __call__
    self.send_data(event.data, write)
  File "/home/ttytu/anaconda3/envs/korcat/lib/python3.9/site-packages/h11/_writers.py", line 91, in send_data
    raise LocalProtocolError("Too much data for declared Content-Length")
h11._util.LocalProtocolError: Too much data for declared Content-Length
[2024-04-03 17:30:46 +0000] [1358944] [ERROR] Exception in ASGI application
Traceback (most recent call last):
  File "/home/ttytu/anaconda3/envs/korcat/lib/python3.9/site-packages/uvicorn/protocols/http/h11_impl.py", line 404, in run_asgi
    result = await app(  # type: ignore[func-returns-value]
  File "/home/ttytu/anaconda3/envs/korcat/lib/python3.9/site-packages/uvicorn/middleware/proxy_headers.py", line 84, in __call__
    return await self.app(scope, receive, send)
  File "/home/ttytu/anaconda3/envs/korcat/lib/python3.9/site-packages/fastapi/applications.py", line 1054, in __call__
    await super().__call__(scope, receive, send)
  File "/home/ttytu/anaconda3/envs/korcat/lib/python3.9/site-packages/starlette/applications.py", line 123, in __call__
    await self.middleware_stack(scope, receive, send)
  File "/home/ttytu/anaconda3/envs/korcat/lib/python3.9/site-packages/starlette/middleware/errors.py", line 186, in __call__
    raise exc
  File "/home/ttytu/anaconda3/envs/korcat/lib/python3.9/site-packages/starlette/middleware/errors.py", line 164, in __call__
    await self.app(scope, receive, _send)
  File "/home/ttytu/anaconda3/envs/korcat/lib/python3.9/site-packages/starlette/middleware/cors.py", line 91, in __call__
    await self.simple_response(scope, receive, send, request_headers=headers)
  File "/home/ttytu/anaconda3/envs/korcat/lib/python3.9/site-packages/starlette/middleware/cors.py", line 146, in simple_response
    await self.app(scope, receive, send)
  File "/home/ttytu/anaconda3/envs/korcat/lib/python3.9/site-packages/starlette/middleware/exceptions.py", line 62, in __call__
    await wrap_app_handling_exceptions(self.app, conn)(scope, receive, send)
  File "/home/ttytu/anaconda3/envs/korcat/lib/python3.9/site-packages/starlette/_exception_handler.py", line 64, in wrapped_app
    raise exc
  File "/home/ttytu/anaconda3/envs/korcat/lib/python3.9/site-packages/starlette/_exception_handler.py", line 53, in wrapped_app
    await app(scope, receive, sender)
  File "/home/ttytu/anaconda3/envs/korcat/lib/python3.9/site-packages/starlette/routing.py", line 762, in __call__
    await self.middleware_stack(scope, receive, send)
  File "/home/ttytu/anaconda3/envs/korcat/lib/python3.9/site-packages/starlette/routing.py", line 782, in app
    await route.handle(scope, receive, send)
  File "/home/ttytu/anaconda3/envs/korcat/lib/python3.9/site-packages/starlette/routing.py", line 297, in handle
    await self.app(scope, receive, send)
  File "/home/ttytu/anaconda3/envs/korcat/lib/python3.9/site-packages/starlette/routing.py", line 77, in app
    await wrap_app_handling_exceptions(app, request)(scope, receive, send)
  File "/home/ttytu/anaconda3/envs/korcat/lib/python3.9/site-packages/starlette/_exception_handler.py", line 64, in wrapped_app
    raise exc
  File "/home/ttytu/anaconda3/envs/korcat/lib/python3.9/site-packages/starlette/_exception_handler.py", line 53, in wrapped_app
    await app(scope, receive, sender)
  File "/home/ttytu/anaconda3/envs/korcat/lib/python3.9/site-packages/starlette/routing.py", line 75, in app
    await response(scope, receive, send)
  File "/home/ttytu/anaconda3/envs/korcat/lib/python3.9/site-packages/starlette/responses.py", line 155, in __call__
    await send({"type": "http.response.body", "body": self.body})
  File "/home/ttytu/anaconda3/envs/korcat/lib/python3.9/site-packages/starlette/_exception_handler.py", line 50, in sender
    await send(message)
  File "/home/ttytu/anaconda3/envs/korcat/lib/python3.9/site-packages/starlette/_exception_handler.py", line 50, in sender
    await send(message)
  File "/home/ttytu/anaconda3/envs/korcat/lib/python3.9/site-packages/starlette/middleware/cors.py", line 152, in send
    await send(message)
  File "/home/ttytu/anaconda3/envs/korcat/lib/python3.9/site-packages/starlette/middleware/errors.py", line 161, in _send
    await send(message)
  File "/home/ttytu/anaconda3/envs/korcat/lib/python3.9/site-packages/uvicorn/protocols/http/h11_impl.py", line 501, in send
    output = self.conn.send(event=h11.Data(data=data))
  File "/home/ttytu/anaconda3/envs/korcat/lib/python3.9/site-packages/h11/_connection.py", line 512, in send
    data_list = self.send_with_data_passthrough(event)
  File "/home/ttytu/anaconda3/envs/korcat/lib/python3.9/site-packages/h11/_connection.py", line 545, in send_with_data_passthrough
    writer(event, data_list.append)
  File "/home/ttytu/anaconda3/envs/korcat/lib/python3.9/site-packages/h11/_writers.py", line 65, in __call__
    self.send_data(event.data, write)
  File "/home/ttytu/anaconda3/envs/korcat/lib/python3.9/site-packages/h11/_writers.py", line 91, in send_data
    raise LocalProtocolError("Too much data for declared Content-Length")
h11._util.LocalProtocolError: Too much data for declared Content-Length
